{
  "Severity": "HIGH",
  "UpdatedAt": "2021-03-13T00:36:36Z",
  "Package": {
    "Ecosystem": "PIP",
    "Name": "django"
  },
  "Advisory": {
    "DatabaseId": 3416,
    "Id": "MDE2OlNlY3VyaXR5QWR2aXNvcnlHSFNBLWZyMjgtNTY5ai01M2M0",
    "GhsaId": "GHSA-fr28-569j-53c4",
    "References": [
      {
        "Url": "https://nvd.nist.gov/vuln/detail/CVE-2020-24584"
      },
      {
        "Url": "https://github.com/advisories/GHSA-fr28-569j-53c4"
      }
    ],
    "Identifiers": [
      {
        "Type": "GHSA",
        "Value": "GHSA-fr28-569j-53c4"
      },
      {
        "Type": "CVE",
        "Value": "CVE-2020-24584"
      }
    ],
    "Description": "An issue was discovered in Django 2.2 before 2.2.16, 3.0 before 3.0.10, and 3.1 before 3.1.1 (when Python 3.7+ is used). The intermediate-level directories of the filesystem cache had the system's standard umask rather than 0o077.",
    "Origin": "UNSPECIFIED",
    "PublishedAt": "2021-03-18T20:30:01Z",
    "Severity": "HIGH",
    "Summary": "Incorrect Default Permissions",
    "UpdatedAt": "2021-03-18T20:30:01Z",
    "WithdrawnAt": ""
  },
  "Versions": [
    {
      "FirstPatchedVersion": {
        "Identifier": "3.1.1"
      },
      "VulnerableVersionRange": "\u003e= 3.1, \u003c 3.1.1"
    },
    {
      "FirstPatchedVersion": {
        "Identifier": "3.0.10"
      },
      "VulnerableVersionRange": "\u003e= 3.0, \u003c 3.0.10"
    },
    {
      "FirstPatchedVersion": {
        "Identifier": "2.2.16"
      },
      "VulnerableVersionRange": "\u003e= 2.2, \u003c 2.2.16"
    }
  ]
}